Workbook

Sheet Testing Scenario
A1: Test Case ID | B1: Module | C1: Test Scenario | D1: Created By | E1: Expected Result | F1: Test Steps | G1: Test Data | H1: Executed By | I1: Actual Result | J1: Status | K1: Attachments
A2: TC-STS-001 | B2: Status | C2: Health check returns server online message [Positive Testing | Smoke Testing | Black-Box] | D2: Dewi F. | E2: 200 OK; body {"message":"Backend Emblaze is Online! 🟢"} | F2: Precondition: Backend container/server is running on port 3000. 1. Open Postman. 2. Set method GET and URL http://localhost:3000/api/status. 3. No special headers. 4. Leave body empty. 5. Click Send. 6. Check the status code, response body and (if relevant) the database record. | G2: - | H2: Dewi F. | I2: 200 OK, {"message":"Backend Emblaze is Online! 🟢"}, 37 ms | J2: Pass
A3: TC-STS-002 | B3: Status | C3: Response is valid JSON with Content-Type application/json [Positive Testing | Functional Testing | Black-Box] | D3: Dewi F. | E3: 200 OK; header Content-Type contains application/json; body parses as JSON with key 'message' (string) | F3: Precondition: Backend container/server is running on port 3000. 1. Open Postman. 2. Set method GET and URL http://localhost:3000/api/status. 3. No special headers. 4. Leave body empty. 5. Click Send. 6. Check the status code, response body and (if relevant) the database record. | G3: - | J3: Not Executed
A4: TC-STS-003 | B4: Status | C4: Response time of health check [Positive Testing | Performance Testing | Black-Box] | D4: Dewi F. | E4: 200 OK; response time < 1000 ms | F4: Precondition: Backend container/server is running on port 3000. 1. Open Postman. 2. Set method GET and URL http://localhost:3000/api/status. 3. No special headers. 4. Leave body empty. 5. Click Send. 6. Check the status code, response body and (if relevant) the database record. | G4: - | H4: Dewi F. | I4: 200 OK, response time 37 ms (< 1000 ms) | J4: Pass
A5: TC-STS-004 | B5: Status | C5: Trailing slash on health check URL [Positive Testing | Functional Testing | Black-Box] | D5: Dewi F. | E5: 200 OK; same body as /api/status (Express default non-strict routing) | F5: Precondition: Backend container/server is running on port 3000. 1. Open Postman. 2. Set method GET and URL http://localhost:3000/api/status/. 3. No special headers. 4. Leave body empty. 5. Click Send. 6. Check the status code, response body and (if relevant) the database record. | G5: - | J5: Not Executed
A6: TC-STS-005 | B6: Status | C6: Unknown query parameters are ignored [Positive Testing | Functional Testing | Black-Box] | D6: Dewi F. | E6: 200 OK; normal message; parameter has no effect | F6: Precondition: Backend container/server is running on port 3000. 1. Open Postman. 2. Set method GET and URL http://localhost:3000/api/status?x=1&debug=true. 3. No special headers. 4. Leave body empty. 5. Click Send. 6. Check the status code, response body and (if relevant) the database record. | G6: - | J6: Not Executed
A7: TC-STS-006 | B7: Status | C7: Repeat health check 10 times for stability [Positive Testing | Regression Testing | Black-Box] | D7: Dewi F. | E7: All 10 responses are 200 with identical body | F7: Precondition: Backend container/server is running on port 3000. 1. Open Postman and create GET http://localhost:3000/api/status. 2. Run the request 10 times with Collection Runner (iterations = 10). 3. Compare all responses. | G7: - | J7: Not Executed
A8: TC-STS-007 | B8: Status | C8: Wrong method POST on health endpoint [Negative Testing | Functional Testing | Black-Box] | D8: Dewi F. | E8: 404 Not Found (route not defined for POST) | F8: Precondition: Backend container/server is running on port 3000. 1. Open Postman. 2. Set method POST and URL http://localhost:3000/api/status. 3. Set header Content-Type: application/json. 4. Body (raw): {} 5. Click Send. 6. Check the status code, response body and (if relevant) the database record. | G8: {} | J8: Not Executed
A9: TC-STS-008 | B9: Status | C9: Wrong method PUT on health endpoint [Negative Testing | Functional Testing | Black-Box] | D9: Dewi F. | E9: 404 Not Found | F9: Precondition: Backend container/server is running on port 3000. 1. Open Postman. 2. Set method PUT and URL http://localhost:3000/api/status. 3. Set header Content-Type: application/json. 4. Body (raw): {} 5. Click Send. 6. Check the status code, response body and (if relevant) the database record. | G9: {} | J9: Not Executed
A10: TC-STS-009 | B10: Status | C10: Wrong method DELETE on health endpoint [Negative Testing | Functional Testing | Black-Box] | D10: Dewi F. | E10: 404 Not Found | F10: Precondition: Backend container/server is running on port 3000. 1. Open Postman. 2. Set method DELETE and URL http://localhost:3000/api/status. 3. No special headers. 4. Leave body empty. 5. Click Send. 6. Check the status code, response body and (if relevant) the database record. | G10: - | J10: Not Executed
A11: TC-STS-010 | B11: Status | C11: Request to a non-existent endpoint [Negative Testing | Functional Testing | Black-Box] | D11: Dewi F. | E11: 404 Not Found; no stack trace or server path is leaked | F11: Precondition: Backend container/server is running on port 3000. 1. Open Postman. 2. Set method GET and URL http://localhost:3000/api/unknown. 3. No special headers. 4. Leave body empty. 5. Click Send. 6. Check the status code, response body and (if relevant) the database record. | G11: - | J11: Not Executed
A12: TC-STS-011 | B12: Status | C12: Request to the API root without a resource [Negative Testing | Functional Testing | Black-Box] | D12: Dewi F. | E12: 404 Not Found | F12: Precondition: Backend container/server is running on port 3000. 1. Open Postman. 2. Set method GET and URL http://localhost:3000/api. 3. No special headers. 4. Leave body empty. 5. Click Send. 6. Check the status code, response body and (if relevant) the database record. | G12: - | J12: Not Executed
A13: TC-STS-012 | B13: Status | C13: CORS header is present for a browser origin [Positive Testing | Compatibility Testing | Black-Box] | D13: Dewi F. | E13: Response header Access-Control-Allow-Origin is present (cors() is enabled) | F13: Precondition: Backend container/server is running on port 3000. 1. Open Postman, GET http://localhost:3000/api/status. 2. Add header Origin: http://localhost:8080. 3. Send and inspect response headers. | G13: Header Origin: http://localhost:8080 | J13: Not Executed
A14: TC-STS-013 | B14: Status | C14: CORS preflight request for the login endpoint [Positive Testing | Compatibility Testing | Black-Box] | D14: Dewi F. | E14: 204 No Content; Access-Control-Allow-Methods includes POST | F14: Precondition: Backend container/server is running on port 3000. 1. Open Postman, OPTIONS http://localhost:3000/api/login. 2. Add headers Origin: http://localhost:8080 and Access-Control-Request-Method: POST. 3. Send and inspect headers. | G14: Origin + Access-Control-Request-Method: POST | J14: Not Executed
A15: TC-STS-014 | B15: Status | C15: Health check while MySQL is stopped [Positive Testing | Integration Testing | Gray-Box] | D15: Dewi F. | E15: 200 OK (route does not depend on the database); other DB-backed endpoints return errors | F15: Precondition: Backend container/server is running on port 3000. 1. Stop the MySQL container. 2. Call GET http://localhost:3000/api/status. 3. Restart MySQL. | G15: - | J15: Not Executed
A16: TC-STS-015 | B16: Status | C16: Server hides technology fingerprint (X-Powered-By) [Negative Testing | Security Testing | Black-Box] | D16: Dewi F. | E16: Header X-Powered-By is absent | F16: Precondition: Backend container/server is running on port 3000. 1. Open Postman. 2. Set method GET and URL http://localhost:3000/api/status. 3. No special headers. 4. Leave body empty. 5. Click Send. 6. Check the status code, response body and (if relevant) the database record. | G16: - | J16: Not Executed
... A19: TC-STS-018 | B19: Status | C19: Server listens on PORT from .env, default 3000 [Positive Testing | Functional Testing | White-Box] | D19: Dewi F. | E19: Server starts on process.env.PORT; if undefined it uses 3000 and logs the startup message | F19: Precondition: Backend container/server is running on port 3000. 1. Set PORT=4000 in .env and start the server. 2. Call GET http://localhost:4000/api/status. 3. Remove PORT and restart; call port 3000. | G19: PORT=4000 / PORT unset | J19: Not Executed
A20: TC-REG-001 | B20: Register | C20: Register a new user with valid data [Positive Testing | Smoke Testing | Black-Box] | D20: Dewi F. | E20: 201 Created; body {"message":"User registered successfully!"}; one new row in users | F20: Precondition: Backend and MySQL are running; table users exists; the username used in this test is not registered yet (unless stated). 1. Open Postman. 2. Set method POST and URL http://localhost:3000/api/register. 3. Set header Content-Type: application/json. 4. Body (raw): {"username": "qa_user01", "password": "Passw0rd!23", "email": "qa_user01@mail.test"} 5. Click Send. 6. Check the status code, response body and (if relevant) the database record. | G20: {"username": "qa_user01", "password": "Passw0rd!23", "email": "qa_user01@mail.test"} | H20: Dewi F. | I20: 201 Created, {"message":"User registered successfully!"}, 139 ms | J20: Pass
A21: TC-REG-002 | B21: Register | C21: Success response format [Positive Testing | Functional Testing | Black-Box] | D21: Dewi F. | E21: 201; Content-Type application/json; body has string field 'message'; no 'password' field | F21: Precondition: Backend and MySQL are running; table users exists; the username used in this test is not registered yet (unless stated). 1. Open Postman. 2. Set method POST and URL http://localhost:3000/api/register. 3. Set header Content-Type: application/json. 4. Body (raw): {"username": "qa_user02", "password": "Passw0rd!23", "email": "qa_user02@mail.test"} 5. Click Send. 6. Check the status code, response body and (if relevant) the database record. | G21: {"username": "qa_user02", "password": "Passw0rd!23", "email": "qa_user02@mail.test"} | J21: Not Executed
A22: TC-REG-003 | B22: Register | C22: Password is stored as a bcrypt hash [Positive Testing | Security Testing | Gray-Box] | D22: Dewi F. | E22: users.password starts with $2b$10$ (or $2a$) and is NOT equal to the plain password | F22: Precondition: Backend and MySQL are running; table users exists; the username used in this test is not registered yet (unless stated). 1. POST /api/register with the data below. 2. In MySQL run: SELECT username,password FROM users WHERE username='qa_user03'; 3. Verify the value is a 60-char bcrypt hash. | G22: {"username": "qa_user03", "password": "Passw0rd!23", "email": "qa_user03@mail.test"} | J22: Not Executed
A23: TC-REG-004 | B23: Register | C23: Same password for two users produces different hashes (salt) [Positive Testing | Security Testing | Gray-Box] | D23: Dewi F. | E23: Two users with the same password have different hash strings | F23: Precondition: Backend and MySQL are running; table users exists; the username used in this test is not registered yet (unless stated). 1. Register qa_user04 and qa_user05 with password Same#Pass123. 2. SELECT password FROM users WHERE username IN ('qa_user04','qa_user05'); 3. Compare both hashes. | G23: username qa_user04 / qa_user05, password Same#Pass123 | J23: Not Executed
A24: TC-REG-005 | B24: Register | C24: Register using form-urlencoded body [Positive Testing | Functional Testing | Black-Box] | D24: Dewi F. | E24: 201 Created; user saved (express.urlencoded is enabled) | F24: Precondition: Backend and MySQL are running; table users exists; the username used in this test is not registered yet (unless stated). 1. Open Postman. 2. Set method POST and URL http://localhost:3000/api/register. 3. Set header Content-Type: application/x-www-form-urlencoded. 4. Body (raw): username=qa_user06&password=Passw0rd!23&email=qa_user06%40mail.test 5. Click Send. 6. Check the status code, response body and (if relevant) the database record. | G24: username=qa_user06&password=Passw0rd!23&email=qa_user06%40mail.test | J24: Not Executed
A25: TC-REG-006 | B25: Register | C25: Username with digits only [Positive Testing | Functional Testing | Black-Box] | D25: Dewi F. | E25: 201 Created | F25: Precondition: Backend and MySQL are running; table users exists; the username used in this test is not registered yet (unless stated). 1. Open Postman. 2. Set method POST and URL http://localhost:3000/api/register. 3. Set header Content-Type: application/json. 4. Body (raw): {"username": "20260001", "password": "Passw0rd!23", "email": "qa_20260001@mail.test"} 5. Click Send. 6. Check the status code, response body and (if relevant) the database record. | G25: {"username": "20260001", "password": "Passw0rd!23", "email": "qa_20260001@mail.test"} | J25: Not Executed
A26: TC-REG-007 | B26: Register | C26: Username with dot and underscore [Positive Testing | Functional Testing | Black-Box] | D26: Dewi F. | E26: 201 Created | F26: Precondition: Backend and MySQL are running; table users exists; the username used in this test is not registered yet (unless stated). 1. Open Postman. 2. Set method POST and URL http://localhost:3000/api/register. 3. Set header Content-Type: application/json. 4. Body (raw): {"username": "qa.user_07", "password": "Passw0rd!23", "email": "qa_user07@mail.test"} 5. Click Send. 6. Check the status code, response body and (if relevant) the database record. | G26: {"username": "qa.user_07", "password": "Passw0rd!23", "email": "qa_user07@mail.test"} | J26: Not Executed
A27: TC-REG-008 | B27: Register | C27: Email with plus tag [Positive Testing | Functional Testing | Black-Box] | D27: Dewi F. | E27: 201 Created | F27: Precondition: Backend and MySQL are running; table users exists; the username used in this test is not registered yet (unless stated). 1. Open Postman. 2. Set method POST and URL http://localhost:3000/api/register. 3. Set header Content-Type: application/json. 4. Body (raw): {"username": "qa_user08", "password": "Passw0rd!23", "email": "qa+tag08@mail.test"} 5. Click Send. 6. Check the status code, response body and (if relevant) the database record. | G27: {"username": "qa_user08", "password": "Passw0rd!23", "email": "qa+tag08@mail.test"} | J27: Not Executed
A28: TC-REG-009 | B28: Register | C28: Email with subdomain [Positive Testing | Functional Testing | Black-Box] | D28: Dewi F. | E28: 201 Created | F28: Precondition: Backend and MySQL are running; table users exists; the username used in this test is not registered yet (unless stated). 1. Open Postman. 2. Set method POST and URL http://localhost:3000/api/register. 3. Set header Content-Type: application/json. 4. Body (raw): {"username": "qa_user09", "password": "Passw0rd!23", "email": "qa09@mail.example.co.id"} 5. Click Send. 6. Check the status code, response body and (if relevant) the database record. | G28: {"username": "qa_user09", "password": "Passw0rd!23", "email": "qa09@mail.example.co.id"} | J28: Not Executed
A29: TC-REG-010 | B29: Register | C29: Username with unicode letters [Positive Testing | Functional Testing | Black-Box] | D29: Dewi F. | E29: 201 Created; username stored and returned correctly (utf8) | F29: Precondition: Backend and MySQL are running; table users exists; the username used in this test is not registered yet (unless stated). 1. Open Postman. 2. Set method POST and URL http://localhost:3000/api/register. 3. Set header Content-Type: application/json. 4. Body (raw): {"username": "müller_10", "password": "Passw0rd!23", "email": "qa_user10@mail.test"} 5. Click Send. 6. Check the status code, response body and (if relevant) the database record. | G29: {"username": "müller_10", "password": "Passw0rd!23", "email": "qa_user10@mail.test"} | J29: Not Executed
A30: TC-REG-011 | B30: Register | C30: Password containing special characters [Positive Testing | Functional Testing | Black-Box] | D30: Dewi F. | E30: 201 Created; user can later log in with the same password | F30: Precondition: Backend and MySQL are running; table users exists; the username used in this test is not registered yet (unless stated). 1. Open Postman. 2. Set method POST and URL http://localhost:3000/api/register. 3. Set header Content-Type: application/json. 4. Body (raw): {"username": "qa_user11", "password": "P@$$w0rd!#%^&*()", "email": "qa_user11@mail.test"} 5. Click Send. 6. Check the status code, response body and (if relevant) the database record. | G30: {"username": "qa_user11", "password": "P@$$w0rd!#%^&*()", "email": "qa_user11@mail.test"} | J30: Not Executed
A31: TC-REG-012 | B31: Register | C31: Long password (64 characters) [Positive Testing | Functional Testing | Black-Box] | D31: Dewi F. | E31: 201 Created | F31: Precondition: Backend and MySQL are running; table users exists; the username used in this test is not registered yet (unless stated). 1. Open Postman. 2. Set method POST and URL http://localhost:3000/api/register. 3. Set header Content-Type: application/json. 4. Body (raw): {"username": "qa_user12", "password": "A1!xxxxxxxxxxxxxxxxxxxxxxxxxxxxxxxxxxxxxxxxxxxxxxxxxxxxxxxxxxxxx", "email": "qa_user12@mail.test"} 5. Click Send. 6. Check the status code, response body and (if relevant) the database record. | G31: {"username": "qa_user12", "password": "A1!xxxxxxxxxxxxxxxxxxxxxxxxxxxxxxxxxxxxxxxxxxxxxxxxxxxxxxxxxxxxx", "email": "qa_user12@mail.test"} | J31: Not Executed
A32: TC-REG-013 | B32: Register | C32: Database record has auto id and created_at [Positive Testing | Integration Testing | Gray-Box] | D32: Dewi F. | E32: New row has auto-increment id and created_at = current timestamp | F32: Precondition: Backend and MySQL are running; table users exists; the username used in this test is not registered yet (unless stated). 1. POST /api/register with the data below. 2. SELECT id,username,email,created_at FROM users WHERE username='qa_user13'; | G32: {"username": "qa_user13", "password": "Passw0rd!23", "email": "qa_user13@mail.test"} | J32: Not Executed
... A44: TC-REG-025 | B44: Register | C44: Missing required field: password [Negative Testing | Functional Testing | Black-Box] | D44: Dewi F. | E44: 400 Bad Request; message states 'password' is required; no row inserted | F44: Precondition: Backend and MySQL are running; table users exists; the username used in this test is not registered yet (unless stated). 1. Open Postman. 2. Set method POST and URL http://localhost:3000/api/register. 3. Set header Content-Type: application/json. 4. Body (raw): {"username": "qa_user01", "email": "qa_user01@mail.test"} 5. Click Send. 6. Check the status code, response body and (if relevant) the database record. | G44: {"username": "qa_user01", "email": "qa_user01@mail.test"} | J44: Not Executed
A45: TC-REG-026 | B45: Register | C45: Missing required field: email [Negative Testing | Functional Testing | Black-Box] | D45: Dewi F. | E45: 400 Bad Request; message states 'email' is required; no row inserted | F45: Precondition: Backend and MySQL are running; table users exists; the username used in this test is not registered yet (unless stated). 1. Open Postman. 2. Set method POST and URL http://localhost:3000/api/register. 3. Set header Content-Type: application/json. 4. Body (raw): {"username": "qa_user01", "password": "Passw0rd!23"} 5. Click Send. 6. Check the status code, response body and (if relevant) the database record. | G45: {"username": "qa_user01", "password": "Passw0rd!23"} | H45: Dewi F. | I45: 500 Internal Server Error, "Username sudah ada atau error database!". Email kosong ditolak database (NOT NULL) tetapi pesannya menyesatkan karena username belum terdaftar. Harusnya 400. | J45: Fail
A46: TC-REG-027 | B46: Register | C46: Empty string for username [Negative Testing | Functional Testing | Black-Box] | D46: Dewi F. | E46: 400 Bad Request; message states 'username' must not be empty | F46: Precondition: Backend and MySQL are running; table users exists; the username used in this test is not registered yet (unless stated). 1. Open Postman. 2. Set method POST and URL http://localhost:3000/api/register. 3. Set header Content-Type: application/json. 4. Body (raw): {"username": "", "password": "Passw0rd!23", "email": "qa_user01@mail.test"} 5. Click Send. 6. Check the status code, response body and (if relevant) the database record. | G46: {"username": "", "password": "Passw0rd!23", "email": "qa_user01@mail.test"} | J46: Not Executed
A47: TC-REG-028 | B47: Register | C47: Empty string for password [Negative Testing | Functional Testing | Black-Box] | D47: Dewi F. | E47: 400 Bad Request; message states 'password' must not be empty | F47: Precondition: Backend and MySQL are running; table users exists; the username used in this test is not registered yet (unless stated). 1. Open Postman. 2. Set method POST and URL http://localhost:3000/api/register. 3. Set header Content-Type: application/json. 4. Body (raw): {"username": "qa_user01", "password": "", "email": "qa_user01@mail.test"} 5. Click Send. 6. Check the status code, response body and (if relevant) the database record. | G47: {"username": "qa_user01", "password": "", "email": "qa_user01@mail.test"} | J47: Not Executed
A48: TC-REG-029 | B48: Register | C48: Empty string for email [Negative Testing | Functional Testing | Black-Box] | D48: Dewi F. | E48: 400 Bad Request; message states 'email' must not be empty | F48: Precondition: Backend and MySQL are running; table users exists; the username used in this test is not registered yet (unless stated). 1. Open Postman. 2. Set method POST and URL http://localhost:3000/api/register. 3. Set header Content-Type: application/json. 4. Body (raw): {"username": "qa_user01", "password": "Passw0rd!23", "email": ""} 5. Click Send. 6. Check the status code, response body and (if relevant) the database record. | G48: {"username": "qa_user01", "password": "Passw0rd!23", "email": ""} | J48: Not Executed
A49: TC-REG-030 | B49: Register | C49: Null value for username [Negative Testing | Functional Testing | Black-Box] | D49: Dewi F. | E49: 400 Bad Request; 'username' must be a string | F49: Precondition: Backend and MySQL are running; table users exists; the username used in this test is not registered yet (unless stated). 1. Open Postman. 2. Set method POST and URL http://localhost:3000/api/register. 3. Set header Content-Type: application/json. 4. Body (raw): {"username": null, "password": "Passw0rd!23", "email": "qa_user01@mail.test"} 5. Click Send. 6. Check the status code, response body and (if relevant) the database record. | G49: {"username": null, "password": "Passw0rd!23", "email": "qa_user01@mail.test"} | J49: Not Executed
A50: TC-REG-031 | B50: Register | C50: Null value for password [Negative Testing | Functional Testing | Black-Box] | D50: Dewi F. | E50: 400 Bad Request; 'password' must be a string | F50: Precondition: Backend and MySQL are running; table users exists; the username used in this test is not registered yet (unless stated). 1. Open Postman. 2. Set method POST and URL http://localhost:3000/api/register. 3. Set header Content-Type: application/json. 4. Body (raw): {"username": "qa_user01", "password": null, "email": "qa_user01@mail.test"} 5. Click Send. 6. Check the status code, response body and (if relevant) the database record. | G50: {"username": "qa_user01", "password": null, "email": "qa_user01@mail.test"} | J50: Not Executed
A51: TC-REG-032 | B51: Register | C51: Null value for email [Negative Testing | Functional Testing | Black-Box] | D51: Dewi F. | E51: 400 Bad Request; 'email' must be a string | F51: Precondition: Backend and MySQL are running; table users exists; the username used in this test is not registered yet (unless stated). 1. Open Postman. 2. Set method POST and URL http://localhost:3000/api/register. 3. Set header Content-Type: application/json. 4. Body (raw): {"username": "qa_user01", "password": "Passw0rd!23", "email": null} 5. Click Send. 6. Check the status code, response body and (if relevant) the database record. | G51: {"username": "qa_user01", "password": "Passw0rd!23", "email": null} | J51: Not Executed
A52: TC-REG-033 | B52: Register | C52: Whitespace-only username [Negative Testing | Functional Testing | Black-Box] | D52: Dewi F. | E52: 400 Bad Request | F52: Precondition: Backend and MySQL are running; table users exists; the username used in this test is not registered yet (unless stated). 1. Open Postman. 2. Set method POST and URL http://localhost:3000/api/register. 3. Set header Content-Type: application/json. 4. Body (raw): {"username": " ", "password": "Passw0rd!23", "email": "qa_user01@mail.test"} 5. Click Send. 6. Check the status code, response body and (if relevant) the database record. | G52: {"username": " ", "password": "Passw0rd!23", "email": "qa_user01@mail.test"} | J52: Not Executed
A53: TC-REG-034 | B53: Register | C53: Whitespace-only password [Negative Testing | Functional Testing | Black-Box] | D53: Dewi F. | E53: 400 Bad Request | F53: Precondition: Backend and MySQL are running; table users exists; the username used in this test is not registered yet (unless stated). 1. Open Postman. 2. Set method POST and URL http://localhost:3000/api/register. 3. Set header Content-Type: application/json. 4. Body (raw): {"username": "qa_ws", "password": " ", "email": "qa_ws@mail.test"} 5. Click Send. 6. Check the status code, response body and (if relevant) the database record. | G53: {"username": "qa_ws", "password": " ", "email": "qa_ws@mail.test"} | J53: Not Executed
...

Sheet Summary
A1: EMBLAZE Backend API - Test Scenario Summary
A3: Total test scenarios | B3: =COUNTA('Testing Scenario'!A2:A252) -> 251
A4: Minimum required by the assignment | B4: 200
A5: Requirement met? | B5: =IF(B3>=B4,"YES","NO") -> YES
A7: By Module | B7: Count | C7: %
A8: Status | B8: =COUNTIF(Classification!$B$2:$B$252,A8) -> 18 | C8: =IF($B$3=0,0,B8/$B$3) -> 0.071713147
A9: Register | B9: =COUNTIF(Classification!$B$2:$B$252,A9) -> 75 | C9: =IF($B$3=0,0,B9/$B$3) -> 0.29880478
A10: Login | B10: =COUNTIF(Classification!$B$2:$B$252,A10) -> 49 | C10: =IF($B$3=0,0,B10/$B$3) -> 0.19521912
A11: Orders | B11: =COUNTIF(Classification!$B$2:$B$252,A11) -> 71 | C11: =IF($B$3=0,0,B11/$B$3) -> 0.28286853
A12: Integration & System | B12: =COUNTIF(Classification!$B$2:$B$252,A12) -> 23 | C12: =IF($B$3=0,0,B12/$B$3) -> 0.091633466
A13: Non-Functional | B13: =COUNTIF(Classification!$B$2:$B$252,A13) -> 15 | C13: =IF($B$3=0,0,B13/$B$3) -> 0.059760956
A14: Total | B14: =SUM(B8:B13) -> 251
A16: By Technique | B16: Count | C16: %
A17: Positive Testing | B17: =COUNTIF(Classification!$D$2:$D$252,A17) -> 91 | C17: =IF($B$3=0,0,B17/$B$3) -> 0.3625498
A18: Negative Testing | B18: =COUNTIF(Classification!$D$2:$D$252,A18) -> 128 | C18: =IF($B$3=0,0,B18/$B$3) -> 0.50996016
A19: Boundary Value Testing | B19: =COUNTIF(Classification!$D$2:$D$252,A19) -> 21 | C19: =IF($B$3=0,0,B19/$B$3) -> 0.083665339
A20: Exploratory Testing | B20: =COUNTIF(Classification!$D$2:$D$252,A20) -> 11 | C20: =IF($B$3=0,0,B20/$B$3) -> 0.043824701
A21: Total | B21: =SUM(B17:B20) -> 251
A23: By Testing Type | B23: Count | C23: %
A24: Functional Testing | B24: =COUNTIF(Classification!$E$2:$E$252,A24) -> 144 | C24: =IF($B$3=0,0,B24/$B$3) -> 0.57370518
A25: Smoke Testing | B25: =COUNTIF(Classification!$E$2:$E$252,A25) -> 6 | C25: =IF($B$3=0,0,B25/$B$3) -> 0.023904382
A26: Regression Testing | B26: =COUNTIF(Classification!$E$2:$E$252,A26) -> 9 | C26: =IF($B$3=0,0,B26/$B$3) -> 0.035856574
A27: Security Testing | B27: =COUNTIF(Classification!$E$2:$E$252,A27) -> 38 | C27: =IF($B$3=0,0,B27/$B$3) -> 0.15139442
A28: Performance Testing | B28: =COUNTIF(Classification!$E$2:$E$252,A28) -> 11 | C28: =IF($B$3=0,0,B28/$B$3) -> 0.043824701
A29: Compatibility Testing | B29: =COUNTIF(Classification!$E$2:$E$252,A29) -> 4 | C29: =IF($B$3=0,0,B29/$B$3) -> 0.015936255
A30: Endurance Testing | B30: =COUNTIF(Classification!$E$2:$E$252,A30) -> 1 | C30: =IF($B$3=0,0,B30/$B$3) -> 0.0039840637
A31: Exploratory Testing | B31: =COUNTIF(Classification!$E$2:$E$252,A31) -> 1 | C31: =IF($B$3=0,0,B31/$B$3) -> 0.0039840637
A32: Integration Testing | B32: =COUNTIF(Classification!$E$2:$E$252,A32) -> 17 | C32: =IF($B$3=0,0,B32/$B$3) -> 0.067729084
A33: Maintainability Testing | B33: =COUNTIF(Classification!$E$2:$E$252,A33) -> 1 | C33: =IF($B$3=0,0,B33/$B$3) -> 0.0039840637
A34: Recoverability Testing | B34: =COUNTIF(Classification!$E$2:$E$252,A34) -> 1 | C34: =IF($B$3=0,0,B34/$B$3) -> 0.0039840637
A35: Reliability Testing | B35: =COUNTIF(Classification!$E$2:$E$252,A35) -> 9 | C35: =IF($B$3=0,0,B35/$B$3) -> 0.035856574
... A39: User Acceptance Testing (UAT) | B39: =COUNTIF(Classification!$E$2:$E$252,A39) -> 2 | C39: =IF($B$3=0,0,B39/$B$3) -> 0.0079681275
A40: Total | B40: =SUM(B24:B39) -> 251
A42: By Test Level | B42: Count | C42: %
A43: Unit Test | B43: =COUNTIF(Classification!$F$2:$F$252,A43) -> 11 | C43: =IF($B$3=0,0,B43/$B$3) -> 0.043824701
A44: Integration Test | B44: =COUNTIF(Classification!$F$2:$F$252,A44) -> 222 | C44: =IF($B$3=0,0,B44/$B$3) -> 0.88446215
A45: System Test | B45: =COUNTIF(Classification!$F$2:$F$252,A45) -> 15 | C45: =IF($B$3=0,0,B45/$B$3) -> 0.059760956
A46: Acceptance Test | B46: =COUNTIF(Classification!$F$2:$F$252,A46) -> 3 | C46: =IF($B$3=0,0,B46/$B$3) -> 0.011952191
A47: Total | B47: =SUM(B43:B46) -> 251
A49: By Test Method (box) | B49: Count | C49: %
...

Sheet Classification
A1: Test Case ID | B1: Module | C1: Endpoint / Feature | D1: Technique | E1: Testing Type | F1: Test Level | G1: Test Method | H1: Execution | I1: Priority
A2: TC-STS-001 | B2: Status | C2: GET /api/status | D2: Positive Testing | E2: Smoke Testing | F2: Integration Test | G2: Black-Box | H2: Automation (Postman) | I2: High
A3: TC-STS-002 | B3: Status | C3: GET /api/status | D3: Positive Testing | E3: Functional Testing | F3: Integration Test | G3: Black-Box | H3: Automation (Postman) | I3: Medium
A4: TC-STS-003 | B4: Status | C4: GET /api/status | D4: Positive Testing | E4: Performance Testing | F4: Integration Test | G4: Black-Box | H4: Automation (Postman) | I4: Medium
A5: TC-STS-004 | B5: Status | C5: GET /api/status | D5: Positive Testing | E5: Functional Testing | F5: Integration Test | G5: Black-Box | H5: Automation (Postman) | I5: Medium
A6: TC-STS-005 | B6: Status | C6: GET /api/status | D6: Positive Testing | E6: Functional Testing | F6: Integration Test | G6: Black-Box | H6: Automation (Postman) | I6: Medium
A7: TC-STS-006 | B7: Status | C7: GET /api/status | D7: Positive Testing | E7: Regression Testing | F7: Integration Test | G7: Black-Box | H7: Automation (Postman) | I7: Medium
A8: TC-STS-007 | B8: Status | C8: GET /api/status | D8: Negative Testing | E8: Functional Testing | F8: Integration Test | G8: Black-Box | H8: Automation (Postman) | I8: Medium
A9: TC-STS-008 | B9: Status | C9: GET /api/status | D9: Negative Testing | E9: Functional Testing | F9: Integration Test | G9: Black-Box | H9: Automation (Postman) | I9: Medium
A10: TC-STS-009 | B10: Status | C10: GET /api/status | D10: Negative Testing | E10: Functional Testing | F10: Integration Test | G10: Black-Box | H10: Automation (Postman) | I10: Medium
A11: TC-STS-010 | B11: Status | C11: GET /api/unknown | D11: Negative Testing | E11: Functional Testing | F11: Integration Test | G11: Black-Box | H11: Automation (Postman) | I11: Medium
A12: TC-STS-011 | B12: Status | C12: GET /api | D12: Negative Testing | E12: Functional Testing | F12: Integration Test | G12: Black-Box | H12: Automation (Postman) | I12: Low
... A252: TC-NFR-015 | B252: Non-Functional | C252: All endpoints | D252: Positive Testing | E252: Security Testing | F252: Unit Test | G252: White-Box | H252: Manual | I252: Medium

Sheet Code Review Notes
A1: Test Case ID | B1: Test Scenario | C1: Prediction from reading server.js (before execution)
A2: TC-STS-014 | B2: Health check while MySQL is stopped | C2: Health route has no DB check, so it reports 'online' even when the DB is down (consider a /health with DB ping).
A3: TC-STS-015 | B3: Server hides technology fingerprint (X-Powered-By) | C3: Likely FAIL: Express sends X-Powered-By: Express by default (use helmet or app.disable('x-powered-by')).
A4: TC-REG-016 | B4: Leading/trailing spaces in username | C4: Likely FAIL: no trim/validation; value is stored with spaces.
A5: TC-REG-019 | B5: Username length = 256 characters (max+1) | C5: Likely FAIL: code returns 500 (MySQL 'Data too long') instead of 400.
A6: TC-REG-021 | B6: Email length = 256 characters (max+1) | C6: Likely FAIL: 500 from database instead of 400.
A7: TC-REG-023 | B7: Password longer than 72 bytes (bcrypt truncation) | C7: Likely FAIL: bcrypt silently truncates at 72 bytes; request returns 201.
A8: TC-REG-024 | B8: Missing required field: username | C8: Likely FAIL: 500 (DB NOT NULL error) with a misleading 'Username sudah ada' message.
A9: TC-REG-025 | B9: Missing required field: password | C9: Likely FAIL: bcrypt.hash(undefined) throws -> 500 with plain text 'Error hashing'.
A10: TC-REG-026 | B10: Missing required field: email | C10: Likely FAIL: 500 (DB NOT NULL error).
A11: TC-REG-027 | B11: Empty string for username | C11: Likely FAIL: no validation; empty string is accepted (201).
A12: TC-REG-028 | B12: Empty string for password | C12: Likely FAIL: no validation; empty string is accepted (201).
... A113: TC-NFR-011 | B113: Consistent JSON error format | C113: Likely FAIL: register returns plain text 'Error hashing'; body-parser errors return HTML.

Sheet Legend
A1: Item | B1: Meaning
A2: Sheet 'Testing Scenario' | B2: Exactly the 11 columns of the lecturer's template. The type/method of testing of each scenario is written under the scenario text in square brackets: [Technique | Testing Type | Test Method].
A3: Technique | B3: Positive Testing = valid input; Negative Testing = invalid input / unexpected condition; Boundary Value Testing = min/max edges; Exploratory Testing = investigate unusual behaviour.
A4: Testing Type | B4: Functional / Smoke / Regression / Security / Performance / Integration / System (End-to-End) / UAT / Reliability / Compatibility (Week 7 slides).
A5: Test Method | B5: Black-Box = inputs/outputs only; Gray-Box = also checks database/logs; White-Box = based on reading server.js.
A6: Test Steps | B6: Starts with the Precondition, then numbered steps that can be copied into Postman.
A7: Expected Result | B7: Behaviour a well-designed API should have (e.g. 400 for invalid input).
A8: Actual Result / Status | B8: Filled for scenarios executed in Postman. Others stay 'Not Executed'. Status: Pass / Fail / Blocked / Not Executed.
A9: Attachments | B9: Put the name of the Postman screenshot file (evidence) here.
A10: Sheet 'Classification' | B10: Supporting data (endpoint, test level, execution, priority) per Test Case ID; used by the Summary sheet.
A11: Sheet 'Code Review Notes' | B11: Predictions from reading server.js before running the tests. 'HIGH RISK' = may crash the Node process.
A12: Environment | B12: http://localhost:3000, Node.js + Express + MySQL 8 (Docker Compose). Tool: Postman. All test data is dummy.
